Task exception was never retrieved
future: <Task finished name='Task-3' coro=<gossip_task() done, defined at broadcast.py:47> exception=AttributeError("module 'asyncio' has no attribute 'timeout'")>
Traceback (most recent call last):
  File "broadcast.py", line 58, in gossip_task
  File "maelstrom.py", line 89, in rpc
AttributeError: module 'asyncio' has no attribute 'timeout'
Task exception was never retrieved
future: <Task finished name='Task-4' coro=<gossip_task() done, defined at broadcast.py:47> exception=AttributeError("module 'asyncio' has no attribute 'timeout'")>
Traceback (most recent call last):
  File "broadcast.py", line 58, in gossip_task
  File "maelstrom.py", line 89, in rpc
AttributeError: module 'asyncio' has no attribute 'timeout'
